Workbook
Name _Hlk189750054: #REF!

Sheet ÍNDICE
B2: COMPONENTES CURRICULARES ANOS FINAIS
B3: EDUCAÇÃO FINANCEIRA
B4: PRÁTICAS EXPERIMENTAIS
B5: PROJETO DE VIDA
B6: REDAÇÃO E LEITURA
B7: ROBÓTICA - PEI 9H
B8: TECNOLOGIA E INOVAÇÃO
B9: MATRIZ SOCIOEMOCIONAL PROJETO DE VIDA

Sheet Educação Financeira
A1: AULA COMPLEMENTAR | B1: CICLO | C1: ANO | D1: BIMESTRE | E1: AULA | F1: HABILIDADE - CÓDIGO | G1: HABILIDADE - TEXTO | H1: UNIDADE TEMÁTICA | I1: OBJETO DE CONHECIMENTO | J1: TÍTULO DA AULA | K1: CONTEÚDO | L1: OBJETIVOS
B2: Anos Finais | C2: 7º | D2: 1º | E2: 1 | F2: - EF05CO10 | G2: - Expressar-se crítica e criativamente na compreensão das mudanças tecnológicas no mundo do trabalho e sobre a evolução da sociedade. | H2: - Planejamento e gestão financeira. | I2: - Orçamento e controle financeiro. | J2: Como nos relacionamos com o dinheiro? ‒ Parte 1 | K2: - Dinheiro no cotidiano. - Relação pessoal com o dinheiro. | L2: - Reconhecer a presença do dinheiro no cotidiano. - Refletir sobre sua relação pessoal com o dinheiro. - Discutir sobre a importância da Educação Financeira nas suas escolhas.
B3: Anos Finais | C3: 7º | D3: 1º | E3: 2 | F3: - EF04GE08 | G3: - Descrever o processo de produção, circulação e consumo de diferentes produtos, reconhecendo as etapas da transformação da matéria-prima em produção de bens e alimentos e comparando a produção de resíduos, no seu município, Estado de São Paulo e em outras regiões do Brasil. | H3: - Planejamento e gestão financeira. | I3: - Orçamento e controle financeiro. | J3: Como nos relacionamos com o dinheiro? ‒ Parte 2 | K3: - Necessidades. - Desejos. - Itens de consumo básico. - Gastos do dia a dia. | L3: - Distinguir necessidades e desejos. - Identificar o custo de itens básicos e supérfluos. - Reconhecer a ideia de escolhas financeiras e suas consequências.
B4: Anos Finais | C4: 7º | D4: 1º | E4: 3 | F4: - EF03GE08A - EF06MA34 | G4: - Associar consumo à produção de resíduos, reconhecendo que o consumo excessivo e o descarte inadequado acarretam problemas socioambientais, em diferentes lugares - Interpretar e desenvolver fluxogramas simples, identificando as relações entre os objetos representados (por exemplo, posição de cidades considerando as estradas que as unem, hierarquia dos funcionários de uma empresa etc.). | H4: - Consumo, sustentabilidade e cidadania. | I4: - Consumo consciente e sustentável. | J4: Consumir com consciência: o que é e por que importa? | K4: - consumo consciente. - consumo sustentável. | L4: - Diferenciar consumo consciente de consumo sustentável, reconhecendo a importância de ambos para as decisões financeiras e para o bem-estar coletivo. - Representar esses conceitos por meio de um esquema visual.
B5: Anos Finais | C5: 7º | D5: 1º | E5: 4 | F5: - EF06MA11 | G5: - Resolver e elaborar problemas com números racionais positivos na representação decimal, envolvendo as quatro operações fundamentais e a potenciação, por meio de estratégias diversas, utilizando estimativas e arredondamentos para verificar a razoabilidade de respostas, com e sem uso de calculadora. | H5: - Planejamento e gestão financeira. | I5: - problemas com valores monetários. | J5: Consumo consciente no dia a dia: analisando nossos gastos ‒ Parte 1 | K5: - Tipos de gastos. - Rendas e despesas. - Entradas e saídas em um orçamento. | L5: - Identificar e classificar seus gastos cotidianos. - Reconhecer as noções básicas de renda e despesas. - Analisar casos envolvendo gastos diários.
B6: Anos Finais | C6: 7º | D6: 1º | E6: 5 | F6: - EF06MA11 | G6: - Resolver e elaborar problemas com números racionais positivos na representação decimal, envolvendo as quatro operações fundamentais e a potenciação, por meio de estratégias diversas, utilizando estimativas e arredondamentos para verificar a razoabilidade de respostas, com e sem uso de calculadora. | H6: - Planejamento e gestão financeira. | I6: - problemas com valores monetários. | J6: Consumo consciente no dia a dia: analisando nossos gastos ‒ Parte 2 | K6: - Tipos de gastos. - Rendas e despesas. - Entradas e saídas em um orçamento. | L6: - Resolver problemas envolvendo gastos diários.
B7: Anos Finais | C7: 7º | D7: 1º | E7: 6 | F7: - EF06MA11 | G7: - Resolver e elaborar problemas com números racionais positivos na representação decimal, envolvendo as quatro operações fundamentais e a potenciação, por meio de estratégias diversas, utilizando estimativas e arredondamentos para verificar a razoabilidade de respostas, com e sem uso de calculadora. | H7: - Planejamento e gestão financeira. | I7: - problemas com valores monetários. | J7: Consumo consciente no dia a dia: analisando nossos gastos ‒ Parte 3 | K7: - Tipos de gastos. - Rendas e despesas. - Entradas e saídas em um orçamento. | L7: - Elaborar problemas envolvendo gastos diários.
B8: Anos Finais | C8: 7º | D8: 1º | E8: 7 | F8: - EF06MA33 | G8: - Planejar e coletar dados de pesquisa referente a práticas sociais escolhidas pelos alunos e fazer uso de planilhas eletrônicas para registro, representação e interpretação das informações, em tabelas, vários tipos de gráficos e texto. | H8: - Planejamento e gestão financeira. | I8: - Orçamento e controle financeiro. | J8: O que é poupar? ‒ Parte 1 | K8: - conceito de poupar. | L8: - Definir o conceito de poupar. - Reconhecer a poupança como uma ação para o futuro.
B9: Anos Finais | C9: 7º | D9: 1º | E9: 8 | F9: - EF06MA11 | G9: - Resolver e elaborar problemas com números racionais positivos na representação decimal, envolvendo as quatro operações fundamentais e a potenciação, por meio de estratégias diversas, utilizando estimativas e arredondamentos para verificar a razoabilidade de respostas, com e sem uso de calculadora. | H9: - Planejamento e gestão financeira. | I9: - Orçamento e controle financeiro. | J9: O que é poupar? ‒ Parte 2 | K9: - conceito de poupar. - conceito de economizar. - estratégias de economia. | L9: - Diferenciar os conceitos de poupar e economizar.
B10: Anos Finais | C10: 7º | D10: 1º | E10: 9 | F10: - EF06MA11 | G10: - Resolver e elaborar problemas com números racionais positivos na representação decimal, envolvendo as quatro operações fundamentais e a potenciação, por meio de estratégias diversas, utilizando estimativas e arredondamentos para verificar a razoabilidade de respostas, com e sem uso de calculadora. | H10: - Planejamento e gestão financeira. | I10: - problemas com valores monetários. | J10: Calculando economias e poupanças ‒ Parte 1 | K10: - Cálculos com valores monetários. | L10: - Realizar cálculos simples para quantificar economias e poupanças, utilizando estratégias diversas e estimativas.
B11: Anos Finais | C11: 7º | D11: 1º | E11: 10 | F11: - EF05MA06 | G11: - Associar as representações 10%, 25%, 50%, 75% e 100% respectivamente à décima parte, quarta parte, metade, três quartos e um inteiro, para calcular porcentagens, utilizando estratégias pessoais, cálculo mental e calculadora, em contextos de educação financeira, entre outros. | H11: - Planejamento e gestão financeira. | I11: - problemas com valores monetários. | J11: Calculando economias e poupanças ‒ Parte 2 | K11: - Cálculos com valores monetários. | L11: - Realizar cálculos simples para quantificar economias e poupanças, utilizando estratégias diversas e estimativas.
B12: Anos Finais | C12: 7º | D12: 1º | E12: 11 | F12: - EF07GE06 | G12: - Analisar a apropriação dos recursos naturais pelas diferentes sociedades e discutir como os processos produtivos, a circulação e o consumo de mercadorias provocam impactos socioambientais e influem nas relações de trabalho e na distribuição de riquezas em diferentes lugares. | H12: - Consumo, sustentabilidade e cidadania. | I12: - Consumo consciente e sustentável. | J12: Consumo sustentável: o impacto das nossas escolhas no bolso e no meio ambiente ‒ Parte 1 | K12: - Decisões de consumo. - Custo/benefício. - Sustentabilidade. | L12: - Reconhecer o impacto das suas decisões de consumo no próprio orçamento, no meio ambiente e na sociedade.
B13: Anos Finais | C13: 7º | D13: 1º | E13: 12 | F13: - EF03GE08A - EF05CI04 | G13: - Associar consumo à produção de resíduos, reconhecendo que o consumo excessivo e o descarte inadequado acarretam problemas socioambientais, em diferentes lugares - Identificar os usos da água nas atividades cotidianas, do campo, no transporte, na indústria, no lazer e na geração de energia, para discutir e propor formas sustentáveis de utilização desse recurso. | H13: - Consumo, sustentabilidade e cidadania. | I13: - Consumo consciente e sustentável. | J13: Consumo sustentável: o impacto das nossas escolhas no bolso e no meio ambiente ‒ Parte 2 | K13: - Impacto do consumo. - Política dos 7Rs. - Sustentabilidade. - Economia. | L13: - Relacionar o consumo excessivo e a produção de lixo. - Propor estratégias de redução, reúso e reciclagem de materiais, visando a economia e o menor impacto.
... B105: Anos Finais | C105: 8º | D105: 4º | E105: 12 | F105: - EF69LP41 | G105: Usar adequadamente ferramentas de apoio a apresentações orais, escolhendo e usando tipos e tamanhos de fontes que permitam boa visualização, topicalizando e/ou organizando o conteúdo em itens, inserindo de forma adequada imagens, gráficos, tabelas, formas e elementos gráficos, dimensionando a quantidade de texto (e imagem) por slide, usando progressivamente e de forma harmônica recursos mais sofisticados como efeitos de transição, slides mestres, layouts personalizados etc. | H105: - Reflexão e fechamento. | I105: - Educação Financeira: Lições e Impactos. | J105: Projeto final: apresentando o Guia da Cidadania Financeira - Parte 2 | K105: Revisão dos principais aprendizados do ano - Reflexão coletiva sobre cidadania financeira | L105: Apresentar o guia de cidadania financeira e refletir sobre a importância da educação financeira.

Sheet Práticas Experimentais
A1: CICLO | B1: ANO | C1: BIMESTRE | D1: AULA | E1: HABILIDADE | F1: OBJETO DE CONHECIMENTO | G1: TÍTULO DA AULA | H1: CONTEÚDO | I1: OBJETIVOS
A2: Anos Finais | B2: 6º | C2: 1º | D2: 1 | E2: EF06CI14 | F2: Forma, estrutura e movimento da Terra | G2: A dança da Terra | H2: Esfericidade da Terra.​ | I2: Compreender o conceito de esfericidade da Terra e como isso influencia a incidência de luz solar.​
A3: Anos Finais | B3: 6º | C3: 1º | D3: 2 | E3: EF06CI11 | F3: Forma, estrutura e movimento da Terra | G3: Como o passado da Terra e o nosso cotidiano se conectam?​ | H3: Tempo histórico, geológico e cronológico. | I3: Compreender o tempo para construir uma visão integrada sobre o desenvolvimento da Terra e das civilizações, relacionando ciência, história e o cotidiano.
A4: Anos Finais | B4: 6º | C4: 1º | D4: 3 | E4: EF06CI14​ | F4: Forma, estrutura e movimento da Terra | G4: Um objeto que cai | H4: Gravidade, aceleração e peso.​ | I4: Identificar os principais conceitos relacionados à gravidade.​
A5: Anos Finais | B5: 6º | C5: 2º | D5: 1 | E5: EF06CI11 | F5: Forma, estrutura e movimento da Terra | G5: O ciclo da água e os estados físicos da matéria | H5: Principais estados físicos da matéria. | I5: Classificar os estados físicos da matéria a partir da análise das características de diferentes objetos.
A6: Anos Finais | B6: 6º | C6: 2º | D6: 2 | E6: EF06CI01 | F6: Separação de materiais | G6: Os métodos de separação de misturas | H6: - Misturas homogêneas e heterogêneas. - Separação de misturas. | I6: Compreender os fênomenos envolvidos em diferentes técnicas de separação de misturas.
A7: Anos Finais | B7: 6º | C7: 2º | D7: 3 | E7: EF06CI12 | F7: Forma, estrutura e movimento da Terra | G7: O processo de fossilização | H7: O que são fósseis e como são formados. | I7: Simular o processo de fossilização.
A8: Anos Finais | B8: 7º | C8: 1º | D8: 1 | E8: EF07CI02​ | F8: Formas de propagação de calor | G8: Como o calor pode mover as máquinas? | H8: Calor e temperatura. | I8: Compreender os principais conceitos relacionados à temperatura, ao calor e à sensação térmica.​
A9: Anos Finais | B9: 7º | C9: 1º | D9: 2 | E9: EF07CI01A​ | F9: Máquinas simples | G9: A engenharia do dia a dia | H9: Máquinas simples. | I9: Identificar o papel do uso de máquinas simples no cotidiano.​
A10: Anos Finais | B10: 7º | C10: 1º | D10: 3 | E10: EF07CI16​ | F10: Placas tectônicas e deriva continental​ | G10: O movimento das placas tectônicas | H10: - Placas tectônicas. - Deriva continental. | I10: Simular os movimentos convergentes, divergentes e transformantes realizados pelas placas tectônicas.
A11: Anos Finais | B11: 7º | C11: 2º | D11: 1 | E11: EF07CI13A | F11: Efeito estufa | G11: Simulando o efeito estufa | H11: Efeito estufa. | I11: Simular, em um sistema pequeno, as condições que levam ao agravamento do efeito estufa.
A12: Anos Finais | B12: 7º | C12: 2º | D12: 2 | E12: EF07CI07 | F12: Diversidade de ecossistemas | G12: Olhando as plantas de perto | H12: Plantas. | I12: Analisar as principais características dos grupos de plantas terrestres.
A13: Anos Finais | B13: 7º | C13: 2º | D13: 3 | E13: EF07CI10A | F13: Programas e indicadores de saúde pública | G13: Diversidade da vida: microorganismos | H13: Microorganismos. | I13: Explorar a presença de micorganismos em diferentes amostras de solo e de água.
... A49: Anos Finais | B49: 9º | C49: 4º | D49: 3 | E49: EF09CI14 | F49: Composição, estrutura e localização do Sistema Solar no Universo | G49: Planetas rochosos | H49: Planetas rochosos do Sistema Solar. | I49: Elaborar maquete dos planetas rochosos do Sistema Solar.

Sheet Projeto de Vida
A1: AULA COMPLEMENTAR | B1: CICLO | C1: ANO | D1: BIMESTRE | E1: TEMA | F1: AULA | G1: DIMENSÃO EM FOCO | H1: COMPREENSÃO | I1: CONTEXTO DA AULA | J1: QUESTÃO ESSENCIAL | K1: ATITUDE | L1: PRÁTICA | M1: HABILIDADE
B2: Anos Finais | C2: 6º | D2: 1º | E2: O início dos Anos Finais é mais do que mudar de turma e professores — é atravessar uma ponte entre ser criança e tornar-se adolescente. Neste projeto, os estudantes vão investigar quem são e quem estão se tornando, construindo um retrato vivo de sua identidade, motivações e escolhas. Ao longo das aulas, eles irão conectar autoconhecimento, convivência, tomada de decisão, planejamento e engajamento, culminando em um produto coletivo que representa sua chegada ao 6º ano. Ao final do projeto, os estudantes terão produzido um “Livro da Transição” (individual ou coletivo), reunindo registros de autoconhecimento, perfis acadêmicos, mapas de afinidades, dilemas de decisão, metas de curto prazo e estratégias de motivação. Esse material servirá como marco simbólico da chegada ao 6º ano e referência para sua jornada no Ensino Fundamental - Anos Finais. | F2: 1 | G2: Autoconhecimento | H2: Assumir e valorizar quem somos é o primeiro passo para nos tornar quem desejamos ser. | I2: Somos diferentes e habitamos o mesmo mundo. Qual será o resultado disso? Esta aula abre o projeto convidando os estudantes a olhar para si mesmos e a compartilhar como se veem. Propõe uma conexão entre família e escola, valorizando percepções mútuas como ponto de partida para a transição. ENTREGA: Livro da Transição: registro inicial de identidade e percepções pessoais/familiares. | J2: - Quais são as características sem as quais eu deixaria de ser quem sou? - O que me torna eu mesmo(a)? - O que minha família diria que são minhas principais características? E eu, o que vejo em mim? | K2: Autoconexão | L2: Reconhecer | M2: AC.6.1 Reconhecer as próprias características físicas e psicológicas.
B3: Anos Finais | C3: 6º | D3: 1º | F3: 2 | G3: Autoconhecimento | H3: Assumir e valorizar quem somos é o primeiro passo para nos tornar quem desejamos ser. | I3: Somos diferentes e habitamos o mesmo mundo. Qual será o resultado disso? Nesta aula, os estudantes iniciam a construção de seu Livro da Transição, criando seu perfil acadêmico a partir da observação de interesses e resultados, integrando-se com a narrativa pessoal da aula 1. ENTREGA: Inclusão do perfil acadêmico no Livro da Transição. | J3: - Quais são as características sem as quais eu deixaria de ser quem sou? - Quem eu sou como estudante? - O que eu já sei sobre mim e meu jeito de aprender? | K3: - Autoconexão - Compromisso consigo mesmo | L3: - Reconhecer - Observar-se | M3: AC.6.1 Reconhecer as próprias características físicas e psicológicas. P.6.1 Criar seu perfil acadêmico com base na observação de interesses e resultados.
B4: Anos Finais | C4: 6º | D4: 1º | F4: 3 | G4: Convivência | H4: Aprender a se expressar com respeito, sem abrir mão da autenticidade, construindo relações de confiança com os demais. | I4: Na escola e na vida, convivemos com pessoas diferentes — mas com algumas, criamos conexões mais fortes. Quem são essas pessoas? O que temos em comum? Como podemos estar juntos de forma positiva e criativa? Dando continuidade ao Livro da Transição, os estudantes exploram afinidades com os colegas, reconhecendo como seus interesses se conectam e constroem pertencimento no novo ciclo. ENTREGA: Mapa de afinidades ou caderno coletivo de interesses no Livro da Transição. | J4: - Quem são as pessoas com as quais eu tenho afinidades? - Com quem eu gosto de estar junto na escola? Por quê? | K4: Abertura para o encontro | L4: Acolher | M4: C.6.1 Formar grupos de interesse com colegas.
B5: Anos Finais | C5: 6º | D5: 1º | F5: 4 | G5: Tomada de decisão | H5: Testar possibilidades de decisão em diferentes cenários e com a participação de diferentes atores. | I5: Escolher entre ir ou não, contar ou esconder, ajudar ou ignorar, se posicionar ou ficar quieto… Todos os dias tomamos decisões. Mas nem sempre é fácil. Por quê? O que torna uma escolha difícil? No Livro da Transição, os estudantes registram dilemas e decisões significativas, discutindo como fatores pessoais e sociais influenciam suas escolhas. ENTREGA: Registro de dilemas e escolhas no Livro da Transição. | J5: É fácil tomar decisões? Por que, na escola, tomar decisões às vezes é difícil? | K5: Coragem para decidir | L5: Refletir | M5: TD.6.1 Compreender porque pode ser difícil tomar decisões.
B6: Anos Finais | C6: 6º | D6: 1º | F6: 5 | G6: Planejamento | H6: Estabelecer objetivos de curto prazo para organizar os estudos e conquistar metas pessoais na escola. | I6: Cada estudante tem uma forma de aprender, se concentrar e se organizar. Descobrir o seu próprio jeito pode ser o primeiro passo para conquistar seus objetivos na escola. Mas o que será que já sabemos sobre nós mesmos como aprendizes? Os estudantes transformam seus perfis e dilemas em metas concretas, registradas como compromissos pessoais no Livro da Transição. ENTREGA: Metas de curto prazo no Livro da Transição. | J6: - Quem eu sou como estudante? - Como eu me organizo para aprender coisas novas? | K6: Compromisso consigo mesmo | L6: Observar-se | M6: P.6.1 Criar seu perfil acadêmico com base na observação de interesses e resultados.
B7: Anos Finais | C7: 6º | D7: 1º | F7: 6 | G7: Engajamento | H7: Manter a motivação necessária para realizar e concluir tarefas com autonomia e empenho pessoal. | I7: Às vezes acordamos animados para realizar nossas tarefas; em outras, parece que nada faz sentido. Identificar o que influencia nossa motivação é um passo importante para aprender a lidar com os altos e baixos e manter o foco mesmo nos dias difíceis. Encerrando o Livro da Transição, os estudantes identificam fatores que influenciam sua motivação e elaboram estratégias pessoais de resiliência. ENTREGA: Diário de ânimo e estratégias de motivação no Livro da Transição. | J7: - Como me sinto quando estou motivado? E demotivado? - O que me dá vontade de aprender? O que me desanima? | K7: Consciência emocional | L7: Observar-se | M7: E.6.1 Diferenciar estados de ânimo motivadores e desmotivadores.
B8: Anos Finais | C8: 6º | D8: 1º | F8: 7 | G8: Engajamento | H8: Manter a motivação necessária para realizar e concluir tarefas com autonomia e empenho pessoal. | I8: Às vezes acordamos animados para realizar nossas tarefas; em outras, parece que nada faz sentido. Identificar o que influencia nossa motivação é um passo importante para aprender a lidar com os altos e baixos e manter o foco mesmo nos dias difíceis. Conclusão do Livro da Transição: os estudantes refletem sobre como emoções e decisões se entrelaçam em sua vida escolar, registrando compromissos para o 6º ano. ENTREGA: Síntese final do Livro da Transição, com compromissos para o novo ciclo. | J8: - Como me sinto quando estou motivado? E demotivado? - É fácil tomar decisões? - Como eu me sinto quando preciso tomar decisões importantes na escola? | K8: - Consciência emocional - Coragem para decidir | L8: - Observar-se - Refletir | M8: E.6.1 Diferenciar estados de ânimo motivadores e desmotivadores. TD.6.1 Compreender porque pode ser difícil tomar decisões.
B9: Anos Finais | C9: 7º | D9: 1º | E9: Cada pessoa tem seus próprios interesses, formas de se comunicar, decisões a tomar e planos para o futuro. No 7º ano, os estudantes estão em uma fase de transição: seus gostos mudam, suas opiniões ganham força e suas responsabilidades aumentam. Nesse contexto, este projeto convida os alunos a investigarem como seus interesses evoluíram, como se comunicam, como tomam decisões e como podem definir metas em diferentes áreas da vida. Ao final, os estudantes criarão um painel de transformações do 7º ano (individual ou coletivo), reunindo registros de seus interesses em mudança, reflexões sobre comunicação e empatia, mapas de decisões, metas pessoais e propostas de engajamento. Esse painel culminará em uma apresentação multimodal que responde à pergunta: “Quem estou me tornando?”. | F9: 1 | G9: Autoconhecimento | H9: Escolher o que nos interessa é também escolher quem estamos nos tornando. | I9: Os interesses mudam com o tempo — o que gostávamos na infância pode já não fazer sentido hoje. E alguns gostos nos acompanham desde sempre. O que será que isso revela sobre nossa história e sobre quem estamos nos tornando? Esta aula abre o projeto, convidando os estudantes a mapear suas transformações de interesses ao longo da vida. O contexto conecta infância e presente, preparando terreno para relacionar mudanças pessoais a futuras escolhas. ENTREGA: Linha do Tempo dos Interesses – registro inicial no “painel de transformações do 7º ano”. | J9: O que mudou e o que permaneceu nos meus interesses até agora? | K9: Autenticidade | L9: Refletir | M9: AC.7.1 Analisar as transformações que ocorreram em seus interesses ao longo dos anos.
B10: Anos Finais | C10: 7º | D10: 1º | F10: 2 | G10: Autoconhecimento | H10: Escolher o que nos interessa é também escolher quem estamos nos tornando. | I10: Os interesses mudam com o tempo — o que gostávamos na infância pode já não fazer sentido hoje. E alguns gostos nos acompanham desde sempre. O que será que isso revela sobre nossa história e sobre quem estamos nos tornando? Os registros se transformam em narrativas ou símbolos que evidenciam o que mudou e o que permaneceu. Assim, ampliam o painel de transformações. ENTREGA: Painel Individual ou Coletivo de Interesses. | J10: O que mudou e o que permaneceu nos meus interesses até agora? | K10: Autenticidade | L10: Refletir | M10: AC.7.1 Analisar as transformações que ocorreram em seus interesses ao longo dos anos.
B11: Anos Finais | C11: 7º | D11: 1º | F11: 3 | G11: Convivência | H11: Utilizar os princípios da comunicação não violenta para expressar-se com respeito, empatia e assertividade. | I11: Às vezes, o jeito como a gente fala pode machucar, ajudar ou confundir. Outras vezes, o silêncio fala mais do que as palavras. Será que sabemos como nossas palavras afetam os outros? E como a forma de escutar também faz diferença? Nesta aula, os estudantes registram, no Painel, reflexões sobre como se comunicam e como a CNV pode ajudar a evitar conflitos (incluindo bullying e exclusão). ENTREGA: Registro CNV no Painel: mural de “Palavras que constroem”. | J11: O que acontece quando eu sei me comunicar bem com os outros? | K11: Consciência comunicativa | L11: Escutar | M11: C.7.1 Refletir sobre os efeitos de diferentes formas de se comunicar em contextos escolares, familiares e comunitários.
B12: Anos Finais | C12: 7º | D12: 1º | F12: 4 | G12: Tomada de Decisão | H12: Tomar decisões baseadas na análise das causas e consequências das situações. | I12: Muitas vezes a gente decide porque algo acontece, alguém fala, ou uma situação muda. Mas e quando isso acontece com pessoas que tomam decisões que afetam o mundo? O que provoca essas decisões? E o que provoca as nossas? Os estudantes comparam decisões pessoais e históricas, registrando no Painel o que perceberam como causas mais relevantes, aproximando suas escolhas das de grandes marcos. ENTREGA: Mapa das Causas – seção do Painel dedicada às decisões. | J12: O que causa a necessidade de tomar uma decisão? | K12: Curiosidade investigativa | L12: Observar-se | M12: TD.7.1 Analisar causas de decisões pessoais e históricas.
B13: Anos Finais | C13: 7º | D13: 1º | F13: 5 | G13: Planejamento | H13: Formular objetivos de curto a médio prazo para diferentes áreas da vida e usar ferramentas para conquistá-los. | I13: Todo mundo tem sonhos, planos e desejos. Mas quais deles podem se tornar realidade em pouco tempo? E o que pode levar um pouco mais? Reconhecer essas metas e pensar em como conquistá-las é uma forma de cuidar da própria vida. A partir da Roda da Vida, os estudantes definem metas, ligando interesses e decisões anteriores. Registram compromissos concretos para diferentes áreas da vida. ENTREGA: Cartões de Metas no Painel. | J13: O que eu quero conquistar a curto e médio prazo? | K13: Intencionalidade | L13: Nomear | M13: P.7.1 Criar uma lista de objetivos de curto e médio prazo para diversas áreas da vida.
B14: Anos Finais | C14: 7º | D14: 1º | F14: 6 | G14: Engajamento | H14: Estar atento e comprometido com as necessidades e demandas do seu entorno. | I14: Vivemos em comunidade. Na escola, em casa e em outros espaços, existem necessidades que nem sempre são ditas. Perceber essas demandas é o primeiro passo para colaborar e se engajar em soluções que fazem a diferença. Os estudantes investigam necessidades na escola, família e comunidade. No Painel, registram propostas coletivas para atendê-las. ENTREGA: Mapa das Necessidades no Painel. | J14: O que as pessoas à minha volta necessitam? | K14: Empatia | L14: Escutar | M14: E.7.1 Perceber e analisar as necessidades e demandas de sua escola, família e comunidade, propondo formas coletivas de atendê-las.
B15: Anos Finais | C15: 7º | D15: 1º | F15: 7 | G15: Autoconhecimento | H15: Escolher o que nos interessa é também escolher quem estamos nos tornando. (Síntese do projeto) | I15: Os interesses mudam com o tempo — o que gostávamos na infância pode já não fazer sentido hoje. E alguns gostos nos acompanham desde sempre. O que será que isso revela sobre nossa história e sobre quem estamos nos tornando? Encerram o painel de transformações conectando interesses, decisões, metas e engajamento. A síntese pode ser multimodal (texto, imagens, áudio, vídeo). ENTREGA: Apresentação Multimodal do painel de transformações. | J15: O que mudou e o que permaneceu nos meus interesses até agora? | K15: - Autenticidade - Intencionalidade | L15: - Refletir - Nomear | M15: AC.7.1 Analisar as transformações que ocorreram em seus interesses ao longo dos anos. P.7.1 Criar uma lista de objetivos de curto e médio prazo para diversas áreas da vida.
B16: Anos Finais | C16: 8º | D16: 1º | E16: Nos pequenos e grandes momentos da vida, lidamos com imprevistos, diferenças, decisões difíceis e o desafio de entender o que é certo ou justo. Ao mesmo tempo, desenvolvemos habilidades únicas, cultivadas pela humanidade ao longo de milênios — imaginar, cuidar, criar, escutar. Neste projeto, os estudantes serão convidados a investigar essas habilidades, a praticar a empatia, a analisar dilemas éticos e a planejar formas de enfrentar frustrações. Ao final, irão elaborar uma Proposta de Ação Pessoal para responder: “Como posso me desenvolver e agir de forma consciente no mundo em que vivo?”. Nesta proposta, deverão reunir reflexões sobre habilidades humanas, empatia, ética, frustrações e engajamento social. Essa proposta será apresentada em formato multimodal (texto, vídeo, painel ou apresentação oral) como marco de sua transição para um papel mais ativo e consciente na sociedade. | F16: 1 | G16: Autoconhecimento | H16: Cultivar habilidades que conectem quem somos hoje com quem desejamos ser no futuro. | I16: Desde que existimos, os seres humanos inventam, aprendem, cuidam, narram, dançam, constroem e sentem. O que será que essas habilidades dizem sobre o que é ser humano? E como elas continuam vivas em nós hoje? A aula inaugura o projeto, levando os estudantes a identificar e valorizar habilidades humanas que os conectam ao passado e ao futuro. Os registros alimentam o início da Proposta de Ação Pessoal. ENTREGA: Mapa das Habilidades Humanas como capítulo inicial da Proposta de Ação Pessoal. | J16: Quais habilidades foram desenvolvidas pela humanidade? | K16: Admiração pelo humano | L16: Nomear | M16: AC.8.1 Conhecer habilidades humanas de diversas naturezas.
B17: Anos Finais | C17: 8º | D17: 1º | F17: 2 | G17: Convivência | H17: Agir com empatia, sendo capaz de compreender as perspectivas e os sentimentos dos outros. | I17: Nem sempre as pessoas pensam como a gente. Às vezes, elas reagem de formas que não entendemos. Mas será que conseguimos enxergar as situações pelos olhos dos outros? Entender como os outros pensam pode mudar nossas relações — e até nossas decisões. Os estudantes exploram a empatia como prática diária, registrando no projeto percepções sobre como enxergar pelos olhos dos outros pode mudar relações e decisões. ENTREGA: Cartas de Perspectiva ou Painel de Múltiplas Vozes integrados à Proposta de Ação Pessoal. | J17: O que os outros estão pensando? | K17: Curiosidade empática | L17: Escutar | M17: C.8.1 Conhecer a perspectiva dos outros em diferentes situações.
B18: Anos Finais | C18: 8º | D18: 1º | F18: 3 | G18: Tomada de decisão | H18: Usar valores éticos como critérios para a tomada de decisão. | I18: Às vezes, a gente faz algo que parece certo, mas depois percebe que pode ter ferido alguém. Outras vezes, somos pressionados a fazer o que todo mundo faz, mesmo que pareça errado. Como saber o que é ético em cada situação? Existe um jeito justo de decidir? Com dilemas éticos reais e fictícios, os estudantes testam ferramentas para avaliar escolhas justas e responsáveis, registrando aprendizados em sua proposta. ENTREGA: Roteiro de Decisão Ética incorporado à Proposta de Ação Pessoal. | J18: Como saber se uma decisão é ética ou não? | K18: Compromisso com o que é justo | L18: Refletir | M18: TD.8.1 Avaliar as implicações éticas de diferentes decisões em contextos pessoais, familiares e sociais.
B19: Anos Finais | C19: 8º | D19: 1º | F19: 4 | G19: Planejamento | H19: Elaborar planos alternativos para lidar com imprevistos e frustrações sem perder de vista seus objetivos. | I19: Nem tudo sai como o planejado. Às vezes, a internet cai, um compromisso atrasa ou simplesmente o cansaço aparece. Como você reage nesses momentos? O que você faz quando algo frustrante acontece e atrapalha seus planos? Por meio de simulações e reflexões, os estudantes elaboram estratégias de enfrentamento, fortalecendo a dimensão prática de sua Proposta de Ação Pessoal. ENTREGA: Kit de Enfrentamento ou Diário do Inesperado integrado à proposta. | J19: Como eu lido com imprevistos e frustrações? | K19: Flexibilidade | L19: Reconhecer | M19: P.8.1 Avaliar como costuma lidar com imprevistos e frustrações.
B20: Anos Finais | C20: 8º | D20: 1º | F20: 5 | G20: Engajamento | H20: Compreender seu papel na sociedade e as formas pelas quais pode contribuir para sua melhoria. | I20: A sociedade em que vivemos é feita por pessoas e instituições. Em meio aos seus avanços e problemas, podemos aprender a enxergar o que merece ser valorizado e o que precisa ser transformado. Essa consciência é o primeiro passo para o engajamento social. Os estudantes analisam avanços e desafios da sociedade, produzindo críticas e elogios fundamentados, que ampliam sua visão de engajamento. ENTREGA: Painel O que Funciona e o que Não Funciona como parte da proposta. | J20: O que há de bom e de ruim na sociedade? | K20: Senso crítico | L20: Argumentar | M20: E.8.1 Criticar e elogiar características da sociedade, incluindo percepções familiares e comunitárias.
B21: Anos Finais | C21: 8º | D21: 1º | F21: 6 | G21: Autoconhecimento | H21: Cultivar habilidades que conectem quem somos hoje com quem desejamos ser no futuro. | I21: Desde que existimos, os seres humanos inventam, aprendem, cuidam, narram, dançam, constroem e sentem. O que será que essas habilidades dizem sobre o que é ser humano? E como elas continuam vivas em nós hoje? Os registros de habilidades e dilemas se transformam em narrativas pessoais sobre ética e humanidade, integrando-se à proposta final. ENTREGA: Galeria de Pessoas Sábias + Linha Ética da Vida Real na proposta. | J21: - Quais habilidades foram desenvolvidas pela humanidade? - Como saber se uma decisão é ética ou não? | K21: - Admiração pelo humano - Compromisso com o que é justo | L21: - Nomear - Refletir | M21: AC.8.1 Conhecer habilidades humanas de diversas naturezas. TD.8.1 Avaliar as implicações éticas de diferentes decisões em contextos pessoais, familiares e sociais.
B22: Anos Finais | C22: 8º | D22: 1º | F22: 7 | G22: Engajamento | H22: Compreender seu papel na sociedade e as formas pelas quais pode contribuir para sua melhoria. | I22: A sociedade em que vivemos é feita por pessoas e instituições. Em meio aos seus avanços e problemas, podemos aprender a enxergar o que merece ser valorizado e o que precisa ser transformado. Essa consciência é o primeiro passo para o engajamento social. Os estudantes finalizam sua Proposta de Ação Pessoal, conectando suas reflexões e estratégias para se desenvolver e agir no mundo. ENTREGA: Apresentação multimodal da Proposta de Ação Pessoal. | J22: - O que há de bom e de ruim na sociedade? - Como eu lido com imprevistos e frustrações? | K22: - Senso crítico - Flexibilidade | L22: - Argumentar - Reconhecer | M22: E.8.1 Criticar e elogiar características da sociedade, incluindo percepções familiares e comunitárias. P.8.1 Avaliar como costuma lidar com imprevistos e frustrações.
B23: Anos Finais | C23: 9º | D23: 1º | E23: Iniciar o último ano do Ensino Fundamental é um momento de balanço e de escolhas. Este projeto convida os estudantes a olhar para suas forças e fragilidades, refletir sobre convivência e bem-estar, avaliar decisões e planejar formas de lidar com imprevistos e frustrações. Ao final, irão propor pequenas melhorias para si mesmos, para a escola e para a comunidade, construindo um retrato coletivo de quem são hoje e de como desejam impactar o mundo ao seu redor. Essa proposta se concretizará por meio de um portfólio coletivo e individual, reunindo autorretratos simbólicos, recursos de força, guias de convivência, mapas de conselheiros, diários do inesperado e propostas de ação no entorno. Esse dossiê marca o início do 9º ano e será compartilhado em uma roda de síntese com colegas e familiares. | F23: 1 | G23: Autoconhecimento | H23: Compreender as fragilidades como parte da identidade, buscando formas saudáveis de lidar com elas e caminhos possíveis de superação. | I23: Todos nós temos partes fortes e partes frágeis. Mas nem sempre olhamos com cuidado para aquilo que nos faz sentir inseguros, com medo ou expostos. Reconhecer essas partes pode nos tornar mais humanos, mais verdadeiros — e mais capazes de crescer. A aula abre o projeto convidando os estudantes a criar um autorretrato simbólico, registrando forças e fragilidades que marcam quem são hoje. ENTREGA: Autorretrato simbólico no dossiê. | J23: Quais partes de mim fazem com que eu me sinta frágil ou vulnerável? | K23: Coragem emocional | L23: Revelar-se | M23: AC.9.1 Reconhecer as próprias fragilidades.
B24: Anos Finais | C24: 9º | D24: 1º | F24: 2 | G24: Autoconhecimento | H24: Compreender as fragilidades como parte da identidade, buscando formas saudáveis de lidar com elas e caminhos possíveis de superação. | I24: Todos nós temos partes fortes e partes frágeis. Mas nem sempre olhamos com cuidado para aquilo que nos faz sentir inseguros, com medo ou expostos. Reconhecer essas partes pode nos tornar mais humanos, mais verdadeiros — e mais capazes de crescer. Em dinâmicas de reflexão e partilha, os estudantes registram no dossiê estratégias de autocuidado e superação. ENTREGA: Página “Meus Recursos de Força”. | J24: Quais partes de mim fazem com que eu me sinta frágil ou vulnerável? | K24: Coragem emocional | L24: Revelar-se | M24: AC.9.1 Reconhecer as próprias fragilidades.
B25: Anos Finais | C25: 9º | D25: 1º | F25: 3 | G25: Convivência | H25: Agir com responsabilidade, considerando o impacto das próprias decisões no bem-estar físico e psicológico dos outros. | I25: Às vezes, pequenos gestos mudam o dia de alguém. Outras vezes, atitudes comuns podem machucar — mesmo sem intenção. O que realmente faz alguém se sentir bem? Como podemos aprender a reconhecer essas necessidades nas outras pessoas? Construção coletiva de um Guia do Bem-Estar, reunindo atitudes que fortalecem a convivência e o cuidado mútuo. ENTREGA: Guia do Bem-Estar no dossiê. | J25: O que faz com que as pessoas se sintam bem? | K25: Cuidado com o outro | L25: Acolher | M25: C.9.1 Conhecer o que gera bem-estar físico e psicológico para os outros.
B26: Anos Finais | C26: 9º | D26: 1º | F26: 4 | G26: Tomada de decisão | H26: Compreender o papel que outras pessoas podem ter no processo de tomada de decisão dos estudantes. | I26: Em muitas situações importantes, temos que decidir sozinhos — mas isso não significa que precisamos estar sozinhos. Pedir ajuda pode parecer sinal de fraqueza, mas e se for inteligência emocional? Como saber quando é hora de contar com alguém? E quem são essas pessoas? Criação de um Mapa de Pessoas-Conselheiras, com registros de quando e como pedir apoio em decisões. ENTREGA: Mapa de Conselheiros no dossiê. | J26: É mais fácil tomar decisões sozinho ou com ajuda de outras pessoas? | K26: Disposição para buscar apoio | L26: Escutar | M26: TD.9.1 Investigar e praticar estratégias de colaboração, pedindo ajuda e oferecendo apoio em processos de tomada de decisão coletiva.
B27: Anos Finais | C27: 9º | D27: 1º | F27: 5 | G27: Planejamento | H27: Planejar a transição para o Ensino Médio com base em quem desejam ser e no que desejam conquistar nessa nova etapa. | I27: Ao final do Ensino Fundamental, muitas mudanças se aproximam: novos desafios, mais responsabilidades e outras formas de viver a escola e a vida. Imaginar como será essa próxima etapa e reconhecer os sentimentos que ela desperta pode nos ajudar a criar caminhos mais seguros e saudáveis para o futuro. E, acima de tudo, nos permite desenvolver estratégias para lidar com os imprevistos e cultivar a confiança em nossa capacidade de superação. A partir de estudos de caso, elaboram o Diário do Inesperado, com estratégias para enfrentar contratempos. ENTREGA: Diário do Inesperado no dossiê. | J27: O que posso fazer para me preparar melhor para os desafios inesperados do dia a dia? | K27: Visão de futuro | L27: Revelar-se | M27: P.9.1 Criar um cenário sobre como imagina sua vida, seus pensamentos e sentimentos em uma próxima etapa da vida, planejando estratégias de resiliência para enfrentar desafios e contratempos.
B28: Anos Finais | C28: 9º | D28: 1º | F28: 6 | G28: Planejamento | H28: Planejar a transição para o Ensino Médio com base em quem desejam ser e no que desejam conquistar nessa nova etapa. | I28: Ao final do Ensino Fundamental, muitas mudanças se aproximam: novos desafios, mais responsabilidades e outras formas de viver a escola e a vida. Imaginar como será essa próxima etapa e reconhecer os sentimentos que ela desperta pode nos ajudar a criar caminhos mais seguros e saudáveis para o futuro. E, acima de tudo, nos permite desenvolver estratégias para lidar com os imprevistos e cultivar a confiança em nossa capacidade de superação. Aprofundando o Diário do Inesperado, os estudantes constroem um Kit de Resiliência (com frases, hábitos, técnicas e recursos simbólicos), registrando como pretendem lidar com desafios no 9º ano. ENTREGA: Kit de Resiliência no dossiê. | J28: O que posso fazer para me preparar melhor para os desafios inesperados do dia a dia? | K28: Visão de futuro | L28: Revelar-se | M28: P.9.1 Criar um cenário sobre como imagina sua vida, seus pensamentos e sentimentos em uma próxima etapa da vida, planejando estratégias de resiliência para enfrentar desafios e contratempos.
B29: Anos Finais | C29: 9º | D29: 1º | F29: 7 | G29: Engajamento | H29: Comprometer-se com ações éticas e conscientes no presente, que contribuam para a construção de futuros melhores para si e para os outros. | I29: Melhorar a própria vida é um movimento que exige autoconhecimento, escolhas conscientes e ação contínua. Quando os jovens se colocam em movimento, eles expandem sua agência e sua capacidade de transformar também o entorno. Em grupos, os estudantes propõem pequenas ações de melhoria na escola, família ou comunidade. Finalizam o Dossiê Retrato do Presente, apresentando-o em uma roda de partilha que celebra conquistas e compromissos. ENTREGA: Proposta de Ação Coletiva + Dossiê completo. | J29: Como posso melhorar a minha vida? | K29: Autonomia | L29: Decidir | M29: E.9.1 Realizar melhorias na vida pessoal.
B30: Anos Finais | C30: 6º | D30: 2º | E30: Minha Voz Conta: conversas difíceis, escolhas importantes Depois de inaugurar o 6º ano olhando para dentro, este bimestre coloca em foco como nos expressamos e decidimos em situações reais de convivência. O projeto convida os estudantes a transformarem a voz individual em voz coletiva. Na aula 1, cada estudante investiga a própria autenticidade (AC.6.2) e redige uma frase-guia sobre como deseja se expressar. Na aula 2, essa voz se torna prática ao treinar fala e escuta respeitosas (C.6.2), gerando frases-modelo que alimentarão um anexo da futura Carta de Convivência. Na aula 3, a turma escolhe um dilema real da convivência escolar e escreve a minuta da Carta (C.6.2). A aula 4 converte o dilema em mapas de decisão (TD.6.2), que na aula 5 são validados em Círculo de Convivência, quando a turma decide coletivamente e finaliza a Carta e o Mapa de Decisão Coletivo (TD.6.2). Para sustentar mudanças reais, a aula 6 aciona o planejamento de microajustes (P.6.2) e prepara a Mostra (convites/cartaz). A aula 7 fecha com autoavaliação de motivação (E.6.2) e a celebração pública: a Mostra “Minha Voz Conta”, em que os combinados são apresentados à comunidade escolar. Assim, cada aula retoma, aprofunda e encaminha o que veio antes, de modo que produto e percurso se constroem juntos: o que sou e como falo (A1–A2) fundamenta o que combinamos (A3), que orienta como decidimos (A4–A5), que gera como vamos manter (A6–A7). Produto: O Material Impresso funciona como caderno de trabalho do projeto; o produto final do bimestre é público e coletivo: a Carta de Convivência da Turma e a Mostra ‘Minha Voz Conta’ com o Mapa de Decisão Coletivo. Roadmap das entregas A1 → “Minha voz”: Frase-guia + lista de características (MI) → alimenta A2/A3. (sem entrega formal) A2 → “Prática de voz”: Frases-modelo (MI) → anexo da Carta na A3. (sem entrega formal) A3 → “Minuta da Carta” (C.6.2): ENTREGA formal (bloco 1) — regras + anexo com frases-modelo. → prepara A4. A4 → “Mapas de decisão” (TD.6.2): rascunhos individuais (MI) → insumo para A5. (sem entrega formal) A5 → “Deliberação e consolidação” (TD.6.2): ENTREGA formal (bloco 2) — Carta final + Mapa de Decisão Coletivo. → prepara A6. A6 → “Sustentação” (P.6.2): ENTREGA formal — Plano 7 dias + preparo visual da Mostra (convites/cartaz). → prepara A7. A7 → “Mostra & celebração” (E.6.2): apresentação pública da Carta e do Mapa + autoavaliação e compromissos. (entrega formal) | F30: 1 | G30: Autoconhecimento | H30: Assumir e valorizar quem somos é o primeiro passo para nos tornar quem desejamos ser. | I30: Quem sou quando estou comigo? A aula propõe um percurso de autorobservação breve para diferenciar “eu íntimo” e “eu público” e tornar explícito o sentido de autenticidade (coerência entre valores, pensamentos, sentimentos, palavras e ações, com respeito e limites). Para mobilizar a atividade AC.6.2, os estudantes serão convidados a identificar traços que consideram autênticos, selecionar evidências pessoais e registrar uma lista curta de características, discernindo o que compartilhar e o que preservar. A aula abre o projeto definindo voz pessoal que será praticada na A2 e servirá de frase-guia na Carta (borda/citações). Produto em construção: frase-guia + lista de características (registro no MI). (sem entrega formal) | J30: Como eu sou quando estou só comigo mesmo? | K30: Autenticidade | L30: Observar-se | M30: AC.6.2 Identificar quais características pessoais promovem a autenticidade.
B31: Anos Finais | C31: 6º | D31: 2º | F31: 2 | G31: Convivência | H31: Aprender a se expressar com respeito, sem abrir mão da autenticidade, construindo relações de confiança com os demais. | I31: Opiniões diferentes, respeito igual A aula propõe um percurso de simulação de divergências e treino de fala/escuta respeitosas para praticar “autenticidade com responsabilidade” (não é sincericídio). Para mobilizar a atividade C.6.2, os estudantes serão convidados a usar eu‑mensagem, paráfrase e pedidos claros, nomeando gatilhos e reparos que preservam a coerência pessoal sem ferir o outro. A aula propõe o uso da frase-guia da A1 para compor frases-modelo que embasarão a minuta da Carta (A3). Produto em construção: frases-modelo (Anexo da Carta). (sem entrega formal) | J31: Como eu posso falar o que penso de forma respeitosa? | K31: Respeito às diferenças | L31: Argumentar | M31: C.6.2 Expor seu ponto de vista de modo respeitoso em grupos com opiniões diversas.
B32: Anos Finais | C32: 6º | D32: 2º | F32: 3 | G32: Convivência | H32: Aprender a se expressar com respeito, sem abrir mão da autenticidade, construindo relações de confiança com os demais. | I32: Preparando nosso círculo A aula propõe um percurso de curadoria de dilemas reais e coescrita de regras de fala que protegem a autenticidade (coerência na expressão) e os limites (segurança/privacidade), vinculando os combinados ao cuidado com os espaços da escola. Para mobilizar a atividade C.6.2, os estudantes serão convidados a propor dilemas, votar prioridades, definir tempos e papéis (mediador/secretário) e ensaiar abertura e réplica com linguagem alinhada a valores e respeito. A proposta deste encontro é a escolha de um dilema que será analisado na A4 e deliberado na A5. Produto em construção: Minuta da Carta de Convivência (regras + anexo de frases-modelo). ENTREGA formal (bloco 1) | J32: Como eu posso falar o que penso de forma respeitosa? | K32: Respeito às diferenças | L32: Argumentar | M32: C.6.2 Expor seu ponto de vista de modo respeitoso em grupos com opiniões diversas.
A33: X | B33: Anos Finais | C33: 6º | D33: 2º | F33: 4 - Aula complementar | G33: Tomada de decisão - Aula complementar | H33: Testar possibilidades de decisão em diferentes cenários e com a participação de diferentes atores. | I33: Antes de decidir, olhe em volta A aula propõe um percurso de leitura de contexto, mapeamento de atores/interesses e previsão de consequências. Para mobilizar a atividade TD.6.2, os estudantes serão convidados a preencher um mapa de decisão com opções possíveis, efeitos prováveis e pessoas a consultar antes de escolher. Este encontro deverá ser dedicado à produção dos rascunhos de mapas que serão base para a decisão coletiva na A5. Produto em construção: Mapas de decisão individuais (MI) → síntese coletiva na A5. (sem entrega formal) | J33: O que é preciso fazer para tomar decisões? | K33: Atenção ao contexto | L33: Observar-se | M33: TD.6.2 Analisar a influência dos contextos na tomada de decisões.
B34: Anos Finais | C34: 6º | D34: 2º | F34: 5 | G34: Tomada de decisão | H34: Testar possibilidades de decisão em diferentes cenários e com a participação de diferentes atores. | I34: Círculo de Convivência (decidir juntos) A aula propõe um percurso de diálogo estruturado em Círculo de Convivência para decidir coletivamente, explicitando “decisões autênticas” como aquelas que alinham valores pessoais à análise de contexto e aos efeitos sobre os outros. Para mobilizar a atividade TD.6.2, os estudantes serão convidados a realizar rodadas de fala com paráfrase obrigatória, registrar propostas/justificativas e pactuar combinados finais, revisando quando necessário (mudei/por quê). Nesta aula está prevista a finalização da Carta (versão final) e a consolidação do Mapa de Decisão Coletivo (para a Mostra). Produto em construção: Carta final + Mapa coletivo. ENTREGA formal (bloco 2) | J34: O que é preciso fazer para tomar decisões? | K34: Atenção ao contexto | L34: Observar-se | M34: TD.6.2 Analisar a influência dos contextos na tomada de decisões.
B35: Anos Finais | C35: 6º | D35: 2º | F35: 6 | G35: Planejamento | H35: Estabelecer objetivos de curto prazo para organizar os estudos e conquistar metas pessoais na escola. | I35: Pequenas mudanças fazem diferença A aula propõe um percurso de avaliação do perfil acadêmico com foco em microajustes praticáveis. Para mobilizar a atividade P.6.2, os estudantes serão convidados a escolher 1–2 mudanças (espaço/rotina/estratégia), definir gatilhos de ação e registrar um microcompromisso de 7 dias com indicadores de verificação. Esta aula conecta Carta/Mapa a hábitos que garantam sua aplicação e organiza convites/cartaz da Mostra. Produto em construção: Plano 7 dias (P.6.2) e preparo da Mostra (visual). ENTREGA formal | J35: Como posso me tornar um estudante melhor? | K35: Disponibilidade | L35: Transformar | M35: P.6.2 Avaliar as mudanças que gostaria de fazer para melhorar seu perfil acadêmico
B36: Anos Finais | C36: 6º | D36: 2º | F36: 7 | G36: Engajamento | H36: Manter a motivação necessária para realizar e concluir tarefas com autonomia e empenho pessoal. | I36: Altos e baixos do meu ânimo (pré-férias) — Mostra & celebração A aula propõe um percurso de autoavaliação afetiva do bimestre e preparação para o recesso. Para mobilizar a atividade E.6.2, os estudantes serão convidados a construir uma linha do tempo de ânimo, identificar gatilhos de motivação/desmotivação e desenhar um plano leve de férias para manter rotinas saudáveis. Esta aula apresenta Carta e Mapa coletivo e pactua compromissos para o retorno, conectando motivação e constância. Produto concluído: Mostra “Minha Voz Conta” + leitura pública. (entrega formal – celebração/síntese) | J36: Quais os efeitos da motivação e da desmotivação na minha vida? | K36: Responsabilidade emocional | L36: Refletir | M36: E.6.2 Reconhecer os efeitos da motivação e da desmotivação na vida pessoal
B37: Anos Finais | C37: 7º | D37: 2º | E37: Minha voz protege: Rotas de Apoio Quando a palavra encontra cuidado, a escola respira melhor. Depois de revisitarem quem são e o que desejam manter em sua vida, os estudantes são convidados a transformar interesses éticos e saudáveis em direção e coragem para falar com respeito, escutar com atenção e agir quando for preciso. Este projeto nasce do eu (o que escolho cultivar) e se abre para o nós (como nos tratamos), atravessando a leitura de consequências do bullying, a organização de um plano e a realização de Rotas de Apoio – sinais de incentivo comportamental, visíveis e simples, que tornam fácil fazer o certo. As rotas orientam: “se você viu/soube/sofreu, o que fazer agora?” (no pátio, corredor, sala, redes). Sequência em cinco movimentos encadeados 1) Autoconhecimento (A1): “o que quero manter/desenvolver” sustenta atitudes de respeito (lista pessoal de interesses éticos e saudáveis). 2) Convivência (A2): prática de Comunicação Não Violenta (CNV) conectada aos interesses da A1, aplicada a micro‑situações presenciais e on‑line. 3) Tomada de decisão (A3): análise de consequências do bullying e do “não agir” para vítima, autor, testemunhas e clima escolar. 4) Planejamento (A4) + Engajamento (A5): plano das Rotas de Apoio e articulação com a escola (validação de locais, linguagem, canais). 5) Convivência + Engajamento (A6) e Síntese (A7): produção, teste e lançamento das Rotas de Apoio; autoavaliação do percurso e compromissos de continuidade. Produto do bimestre Rotas de Apoio da escola (sinais de incentivo comportamental): placas/cartazes discretos e objetivos, posicionados em pontos‑chave (corredores, pátio, biblioteca, banheiros, sala), com passos simples (“viu/soube/sofreu? 1) pare e respire; 2) procure X; 3) registre Y; 4) não compartilhe; 5) peça ajuda”) e contatos/canais de escuta protegida definidos com a escola. Onde a infraestrutura permitir, adicionar QR para guia/escuta; onde não, manter apenas rotas visuais. O Material Impresso é utilizado como caderno consumível ao longo das aulas (mapas, roteiros, checklists, registros)." | F37: 1 | G37: Autoconhecimento | H37: Escolher o que nos interessa é também escolher quem estamos nos tornando. | I37: Interesses que sustentam o respeito A aula propõe um percurso de mapeamento e priorização de interesses éticos e saudáveis e sua conexão com atitudes antibullying (incluir, ajudar, não compartilhar humilhações). Para mobilizar AC.7.2, os estudantes serão convidados a listar e selecionar interesses que ‘fazem a vida ser melhor’, registrando exemplos de comportamentos coerentes com esses interesses (na escola e nas redes). Este encontro deverá ser dedicado à seleção do top 3 e ao vínculo com atitudes de respeito que embasarão a comunicação das Rotas de Apoio. | J37: Eu me interesso por coisas que fazem a minha vida ser melhor? | K37: Responsabilidade pessoal | L37: Decidir | M37: AC.7.2 Fazer uma lista pessoal de interesses éticos e saudáveis para manter e/ou desenvolver.
A38: X | B38: Anos Finais | C38: 7º | D38: 2º | F38: 2 - complementar | G38: Convivência - complementar | H38: Utilizar os princípios da comunicação não violenta para expressar-se com respeito, empatia e assertividade. | I38: Falar com respeito, agir com cooperação (CNV em ação) A aula propõe um percurso de treino de CNV, conectado ao Top 3 da A1, aplicado a micro‑situações de bullying (exclusão, apelidos, prints). Para mobilizar C.7.2, as equipes assumem papéis (mediador, porta‑voz, observador CNV) e escrevem roteiros breves (eu‑mensagem, pedidos claros, acordos). Este encontro deverá ser dedicado à produção dos cartões ‘Eu digo / Eu escuto / Eu peço’ e aos ensaios curtos com rubrica de respeito e clareza. | J38: A forma como eu falo com os outros me ajuda ou me atrapalha? | K38: Auto-observação | L38: Refletir | M38: C.7.2 Avaliar e ampliar as formas de comunicação, assumindo papéis ativos em grupos e propondo estratégias de cooperação.
B39: Anos Finais | C39: 7º | D39: 2º | F39: 3 | G39: Tomada de decisão | H39: Tomar decisões baseadas na análise das causas e consequências das situações. | I39: Se a gente não faz nada… (analisando consequências) A aula propõe um percurso de análise das consequências do bullying e do ‘não agir’ para vítima, autor, testemunhas e clima escolar (presencial e nas redes). Para mobilizar TD.7.2, os estudantes comparam alternativas de resposta (intervir, procurar ajuda, registrar evidências) e preveem efeitos de curto/médio prazo. Este encontro deverá ser dedicado à produção dos Mapas de Consequências que orientarão o plano das Rotas. | J39: Que tipo de consequências uma decisão pode ter? | K39: Responsabilidade pelas consequências | L39: Refletir | M39: TD.7.2 Analisar consequências de decisões pessoais e históricas.
B40: Anos Finais | C40: 7º | D40: 2º | F40: 4 | G40: Planejamento | H40: Definir objetivos de curto e médio prazo em diferentes áreas da vida, utilizando estratégias e ferramentas para alcançá-los. | I40: Do papel à parede: Plano das Rotas de Apoio A aula propõe um percurso de planejamento das Rotas de Apoio: meta (clareza e acolhimento), locais estratégicos (pátio, corredor, sala, banheiros), mensagens simples (passos ‘viu/soube/sofreu’), contatos/canais, responsáveis e cronograma. Para mobilizar P.7.2, a turma define evidências de sucesso (alcance, compreensão, acesso a apoio). Este encontro deverá ser dedicado à finalização do Plano das Rotas. | J40: Como posso me organizar para realizar de fato meus objetivos? | K40: Organização e perseverança | L40: Decidir | M40: P.7.2 Utilizar uma estrátegia de planejamento para organizar a realização dos seus objetivos.
...

Sheet Redação e Leitura
A1: Ano/Série | B1: Bimestre | C1: Semana | D1: Título GPS Semanal | E1: Aula | F1: Prática de linguagem | G1: Proposta | H1: Gênero textual | I1: Eixo Temático | J1: Sugestão 1 | K1: Sugestão 2 | L1: Sugestão 3 | M1: Práticas pedagógicas | N1: Plataforma | O1: Objetivos de aprendizagem | P1: Objetos de conhecimento | Q1: Habilidade - Código | R1: Habilidade - Texto
A2: 6º | B2: 1º | C2: 1 | D2: Práticas de Leitura e Escrita do Bimestre | Elaboração do Projeto de Texto 1 | E2: 1 | F2: Leitura | G2: P1 | H2: Notícia | I2: Histórias que a Escola Conta | J2: Harry Potter e a Pedra Filosofal | K2: Diário de um Banana: Rodrick é o Cara | L2: O Menino Maluquinho | M2: - Apresentação do eixo temático e da obra selecionada para o bimestre - Predição guiada - Leitura - Seleção de trechos relevantes (grifos na plataforma de leitura) | N2: Leia SP | O2: - Relacionar o tema bimestral à obra literária selecionada para o bimestre. - Formular hipóteses sobre o enredo da obra literária utilizando a estratégia de predição guiada. | P2: - Reconstrução das condições de produção, circulação e recepção - Adesão às práticas de leitura | Q2: - EF69LP46 - EF69LP49 | R2: - Participar de práticas de compartilhamento de leitura/recepção de obras literárias/manifestações artísticas, tecendo, quando possível, comentários de ordem estética e afetiva. - Mostrar-se interessado e envolvido pela leitura de livros de literatura e por outras produções culturais do campo e receptivo a textos que rompam com seu universo de expectativas, que representem um desafio em relação às suas possibilidades atuais e suas experiências anteriores de leitura, apoiando-se nas marcas linguísticas, em seu conhecimento sobre os gêneros e a temática e nas orientações dadas pelo professor.
A3: 6º | B3: 1º | C3: 1 | D3: Práticas de Leitura e Escrita do Bimestre | Elaboração do Projeto de Texto 1 | E3: 2 | F3: Produção de textos | G3: P1 | H3: Notícia | I3: Histórias que a Escola Conta | J3: Harry Potter e a Pedra Filosofal | K3: Diário de um Banana: Rodrick é o Cara | L3: O Menino Maluquinho | M3: - Definir 5W1H com base nas anotações de leitura - Rascunhar pauta e possíveis manchetes - Listar trechos da obra escolhida que servirão como “fontes”/aspas | N3: Leia SP | O3: - Planejar notícia com título e informações essenciais (5W1H); - Relacionar elementos da leitura da obra ao planejamento da produção. | P3: Estratégias de produção: planejamento de textos informativos | Q3: EF67LP09 | R3: Planejar notícia impressa e para circulação em outras mídias (rádio ou TV/vídeo), tendo em vista as condições de produção, do texto – objetivo, leitores/espectadores, veículos e mídia de circulação etc. –, a partir da escolha do fato a ser noticiado, do levantamento de dados e informações sobre o fato.
